Workbook

Sheet Summary
A1: EdgeCipline — Pre-Launch Verification
A2: Web first (W1–W6), then Android (A1–A3). Any F in W1–W3 or A1–A2 = do not launch.
A4: Section | B4: Total | C4: Pass | D4: Fail | E4: Not done | F4: Status
A5: W1. Production config — read before you click | B5: =COUNTIFS(Checklist!$C:$C,A5,Checklist!$D:$D,"<>") | C5: =COUNTIFS(Checklist!$C:$C,A5,Checklist!$F:$F,"P") | D5: =COUNTIFS(Checklist!$C:$C,A5,Checklist!$F:$F,"F") | E5: =B5-C5-D5-COUNTIFS(Checklist!$C:$C,A5,Checklist!$F:$F,"N/A") | F5: =IF(D5>0,"BLOCKED",IF(E5>0,"IN PROGRESS","DONE"))
A6: W2. Lockout paths — if these break, nobody can get in | B6: =COUNTIFS(Checklist!$C:$C,A6,Checklist!$D:$D,"<>") | C6: =COUNTIFS(Checklist!$C:$C,A6,Checklist!$F:$F,"P") | D6: =COUNTIFS(Checklist!$C:$C,A6,Checklist!$F:$F,"F") | E6: =B6-C6-D6-COUNTIFS(Checklist!$C:$C,A6,Checklist!$F:$F,"N/A") | F6: =IF(D6>0,"BLOCKED",IF(E6>0,"IN PROGRESS","DONE"))
A7: W3. Money — irreversible if wrong | B7: =COUNTIFS(Checklist!$C:$C,A7,Checklist!$D:$D,"<>") | C7: =COUNTIFS(Checklist!$C:$C,A7,Checklist!$F:$F,"P") | D7: =COUNTIFS(Checklist!$C:$C,A7,Checklist!$F:$F,"F") | E7: =B7-C7-D7-COUNTIFS(Checklist!$C:$C,A7,Checklist!$F:$F,"N/A") | F7: =IF(D7>0,"BLOCKED",IF(E7>0,"IN PROGRESS","DONE"))
A8: W4. Core loop on web | B8: =COUNTIFS(Checklist!$C:$C,A8,Checklist!$D:$D,"<>") | C8: =COUNTIFS(Checklist!$C:$C,A8,Checklist!$F:$F,"P") | D8: =COUNTIFS(Checklist!$C:$C,A8,Checklist!$F:$F,"F") | E8: =B8-C8-D8-COUNTIFS(Checklist!$C:$C,A8,Checklist!$F:$F,"N/A") | F8: =IF(D8>0,"BLOCKED",IF(E8>0,"IN PROGRESS","DONE"))
A9: W5. Support is reachable — your post-launch safety net | B9: =COUNTIFS(Checklist!$C:$C,A9,Checklist!$D:$D,"<>") | C9: =COUNTIFS(Checklist!$C:$C,A9,Checklist!$F:$F,"P") | D9: =COUNTIFS(Checklist!$C:$C,A9,Checklist!$F:$F,"F") | E9: =B9-C9-D9-COUNTIFS(Checklist!$C:$C,A9,Checklist!$F:$F,"N/A") | F9: =IF(D9>0,"BLOCKED",IF(E9>0,"IN PROGRESS","DONE"))
A10: W6. Admin sanity | B10: =COUNTIFS(Checklist!$C:$C,A10,Checklist!$D:$D,"<>") | C10: =COUNTIFS(Checklist!$C:$C,A10,Checklist!$F:$F,"P") | D10: =COUNTIFS(Checklist!$C:$C,A10,Checklist!$F:$F,"F") | E10: =B10-C10-D10-COUNTIFS(Checklist!$C:$C,A10,Checklist!$F:$F,"N/A") | F10: =IF(D10>0,"BLOCKED",IF(E10>0,"IN PROGRESS","DONE"))
A11: A1. Store compliance — suspension risk | B11: =COUNTIFS(Checklist!$C:$C,A11,Checklist!$D:$D,"<>") | C11: =COUNTIFS(Checklist!$C:$C,A11,Checklist!$F:$F,"P") | D11: =COUNTIFS(Checklist!$C:$C,A11,Checklist!$F:$F,"F") | E11: =B11-C11-D11-COUNTIFS(Checklist!$C:$C,A11,Checklist!$F:$F,"N/A") | F11: =IF(D11>0,"BLOCKED",IF(E11>0,"IN PROGRESS","DONE"))
A12: A2. Google Play money | B12: =COUNTIFS(Checklist!$C:$C,A12,Checklist!$D:$D,"<>") | C12: =COUNTIFS(Checklist!$C:$C,A12,Checklist!$F:$F,"P") | D12: =COUNTIFS(Checklist!$C:$C,A12,Checklist!$F:$F,"F") | E12: =B12-C12-D12-COUNTIFS(Checklist!$C:$C,A12,Checklist!$F:$F,"N/A") | F12: =IF(D12>0,"BLOCKED",IF(E12>0,"IN PROGRESS","DONE"))
A13: A3. App-only behaviour | B13: =COUNTIFS(Checklist!$C:$C,A13,Checklist!$D:$D,"<>") | C13: =COUNTIFS(Checklist!$C:$C,A13,Checklist!$F:$F,"P") | D13: =COUNTIFS(Checklist!$C:$C,A13,Checklist!$F:$F,"F") | E13: =B13-C13-D13-COUNTIFS(Checklist!$C:$C,A13,Checklist!$F:$F,"N/A") | F13: =IF(D13>0,"BLOCKED",IF(E13>0,"IN PROGRESS","DONE"))
A14: Before deploy | B14: =COUNTIFS(Checklist!$C:$C,A14,Checklist!$D:$D,"<>") | C14: =COUNTIFS(Checklist!$C:$C,A14,Checklist!$F:$F,"P") | D14: =COUNTIFS(Checklist!$C:$C,A14,Checklist!$F:$F,"F") | E14: =B14-C14-D14-COUNTIFS(Checklist!$C:$C,A14,Checklist!$F:$F,"N/A") | F14: =IF(D14>0,"BLOCKED",IF(E14>0,"IN PROGRESS","DONE"))
A16: LAUNCH DECISION | B16: =IF(COUNTIF(Checklist!$F:$F,"F")>0,"DO NOT LAUNCH — fix the F items",IF(SUM(E5:E14)>0,"NOT READY — tests remaining","READY TO LAUNCH"))
A18: Rollback build / tag:
A19: Signed off by / date:

Sheet Checklist
A1: # | B1: Pass | C1: Section | D1: Test | E1: Expected result | F1: Result | G1: Tested by | H1: Date | I1: Notes / bug link
A2: Pass 1 — Web › W1. Production config — read before you click
A3: 1 | B3: Pass 1 — Web | C3: W1. Production config — read before you click | D3: Backend .env (prod): Razorpay key is LIVE (not rzp_test_), MONGO_URI is the production cluster and MONGO_URI_LOCAL is NOT set, Cloudinary is the production account, mail provider is production, SUPPORT_TICKETS_ENABLED=true, free-trade limit enforcement is on.
A4: 2 | B4: Pass 1 — Web | C4: W1. Production config — read before you click | D4: Web build flags: NEXT_PUBLIC_PAYMENTS_ENABLED=true, NEXT_PUBLIC_PLAY_BILLING_ENABLED=false, NEXT_PUBLIC_RAZORPAY_KEY_ID is the live key | E4: Confirm the checkout modal does NOT say "Sandbox demo".
A5: 3 | B5: Pass 1 — Web | C5: W1. Production config — read before you click | D5: CORS: allowlist contains only the production frontend origin(s) | E5: No localhost, no old Cloudflare preview URLs. CORS_DEBUG off.
A6: 4 | B6: Pass 1 — Web | C6: W1. Production config — read before you click | D6: Secrets: JWT / admin JWT secrets differ from staging/dev and are not committed to git.
A7: 5 | B7: Pass 1 — Web | C7: W1. Production config — read before you click | D7: HTTPS: site and API load over HTTPS; browser console shows no mixed-content or CORS errors on the dashboard.
A8: 6 | B8: Pass 1 — Web | C8: W1. Production config — read before you click | D8: Database backup: Atlas (or host) shows automated backups enabled and at least one snapshot exists.
A9: 7 | B9: Pass 1 — Web | C9: W1. Production config — read before you click | D9: Indexes & seeds: syncIndexes.js run once on production; production admin exists (ensureAdminUser.js --list); knowledge base seeded (/support shows articles, not "Guides are on their way").
A10: Pass 1 — Web › W2. Lockout paths — if these break, nobody can get in
A11: 8 | B11: Pass 1 — Web | C11: W2. Lockout paths — if these break, nobody can get in | D11: Register → OTP. Register a fresh email | E11: OTP email arrives within a minute from the production mail provider; correct OTP works; wrong OTP rejected; resend works.
A12: 9 | B12: Pass 1 — Web | C12: W2. Lockout paths — if these break, nobody can get in | D12: Accept terms | E12: New account is asked to accept Terms once, then never again.
A13: 10 | B13: Pass 1 — Web | C13: W2. Lockout paths — if these break, nobody can get in | D13: Login / session / logout | E13: Login works; refresh keeps you in; open a second tab → still logged in; logout in one tab logs out the other.
A14: 11 | B14: Pass 1 — Web | C14: W2. Lockout paths — if these break, nobody can get in | D14: Forgot password | E14: Request reset → email arrives → link opens /reset-password → new password works, old one does not, the link cannot be reused.
A15: 12 | B15: Pass 1 — Web | C15: W2. Lockout paths — if these break, nobody can get in | D15: Admin login. /admin/login with the real production admin (not the local seed) | E15: admin dashboard loads; wrong password rejected. (3 failures lock for 1 hour.)
A16: 13 | B16: Pass 1 — Web | C16: W2. Lockout paths — if these break, nobody can get in | D16: Admin routes blocked for users. Logged in as a normal user, open /admin/users directly | E16: refused, not rendered.
A17: Pass 1 — Web › W3. Money — irreversible if wrong
A18: 14 | B18: Pass 1 — Web | C18: W3. Money — irreversible if wrong | D18: Real Razorpay payment. Buy the cheapest plan with a real card/UPI on the LIVE key | E18: Premium unlocks immediately without a refresh; Settings shows plan + correct expiry; payment appears in /admin/payments with the same order id and amount as the Razorpay dashboard.
A19: 15 | B19: Pass 1 — Web | C19: W3. Money — irreversible if wrong | D19: Payment failure. Start checkout and cancel / use a failing method | E19: clear error, still free plan, no charge, retry works without a duplicate order.
A20: 16 | B20: Pass 1 — Web | C20: W3. Money — irreversible if wrong | D20: Pricing matches | E20: Plan cards on the paywall, the amount on the pay button, and what Razorpay actually charged are the same numbers (monthly / 3-month / 6-month).
A21: 17 | B21: Pass 1 — Web | C21: W3. Money — irreversible if wrong | D21: Coupon (if you launch with one) | E21: Valid code reduces the payable amount on the button and the charged amount matches; invalid/disabled code shows "This code isn't valid".
A22: 18 | B22: Pass 1 — Web | C22: W3. Money — irreversible if wrong | D22: Premium survives re-login | E22: Log out and back in → still Premium.
A23: Pass 1 — Web › W4. Core loop on web
A24: 19 | B24: Pass 1 — Web | C24: W4. Core loop on web | D24: Onboarding | E24: New account → onboarding → create a setup → lands on the dashboard; Growth Path shows "Build Setup" as done.
A25: 20 | B25: Pass 1 — Web | C25: W4. Core loop on web | D25: Manual trade — Forex. Log one trade filling Setup / Pattern, SL/TP, R:R, mood, confidence, emotions | E25: saves; appears in Trades; detail/edit shows every field intact.
A26: 21 | B26: Pass 1 — Web | C26: W4. Core loop on web | D26: Manual trade — Indian (Options + Equity). Switch to India market, log one of each | E26: strike/CE-PE (options) or symbol/qty (equity), SL/TP, trade type, screenshot all saved.
A27: 22 | B27: Pass 1 — Web | C27: W4. Core loop on web | D27: OCR upload. /upload-trade with a real broker screenshot (NOT EURUSD) | E27: extracted pair/entry/exit/P&L match the image — never the generic EURUSD / 0.01 lot / +50 sample. Then upload a blurry/non-chart image → clear "could not extract" error, no invented trade.
A28: 23 | B28: Pass 1 — Web | C28: W4. Core loop on web | D28: Free-trade limit. On a free account log a 3rd trade in one market | E28: limit dialog ("You've used your 2 free … trades"), and it opens the Razorpay paywall. Switch market → that market still allows its own 2 trades. Existing trades still viewable/editable.
A29: 24 | B29: Pass 1 — Web | C29: W4. Core loop on web | D29: Dashboard reflects trades | E29: P&L / trade count match what you logged; market switcher changes the numbers; no stale data after adding a trade.
A30: 25 | B30: Pass 1 — Web | C30: W4. Core loop on web | D30: Checklist image preview | E30: Checklist → expand a setup with reference images → click a thumbnail → the × close button is visible top-right and closes it. Also check at a short window height (reported bug).
A31: 26 | B31: Pass 1 — Web | C31: W4. Core loop on web | D31: Phone width once | E31: Resize the browser to ~375px: Add Trade (both markets), the paywall, and the Help widget are usable — no cut-off buttons, no horizontal scroll.
A32: Pass 1 — Web › W5. Support is reachable — your post-launch safety net
A33: 27 | B33: Pass 1 — Web | C33: W5. Support is reachable — your post-launch safety net | D33: /support logged out in a private window | E33: page renders with articles + contact options (this URL goes to Google/Apple reviewers).
A34: 28 | B34: Pass 1 — Web | C34: W5. Support is reachable — your post-launch safety net | D34: Open a ticket as a user from /support/tickets/new with a screenshot | E34: appears in /admin/support within seconds; the attachment opens for the admin; pasting the raw image URL in a logged-out window returns 404 (private).
A35: 29 | B35: Pass 1 — Web | C35: W5. Support is reachable — your post-launch safety net | D35: Report an issue from the app. OCR review screen → "Report OCR Issue" → submit with a screenshot | E35: success screen shows a ticket code (EC-…); the ticket has a Bug report badge in /support/tickets and in /admin/support; the admin context panel shows the OCR values table.
A36: 30 | B36: Pass 1 — Web | C36: W5. Support is reachable — your post-launch safety net | D36: Admin reply → user. Reply from /admin/support | E36: user receives the notification/email and sees the reply on the ticket.
A37: 31 | B37: Pass 1 — Web | C37: W5. Support is reachable — your post-launch safety net | D37: Issue → ticket sync. In /admin/issues, mark that report Fixed with a summary | E37: the ticket gets a Support reply with the summary and becomes Resolved.
A38: 32 | B38: Pass 1 — Web | C38: W5. Support is reachable — your post-launch safety net | D38: Floating Help widget opens on the dashboard, answers a question or hands off to "Create a support ticket"; WhatsApp / email links open with the correct number/address.
A39: Pass 1 — Web › W6. Admin sanity
A40: 33 | B40: Pass 1 — Web | C40: W6. Admin sanity | D40: /admin/users shows the accounts you just created with the correct plan; /admin/trades shows the trades you logged (including Setup / SL / TP fields); /admin/payments shows the real payment from W3.
...
